[2022-03-23 09:54:59,441] {taskinstance.py:1037} INFO - Dependencies all met for <TaskInstance: s3_big5.s3filetransformoperator manual__2022-03-23T09:54:58.263272+00:00 [queued]>
[2022-03-23 09:54:59,458] {taskinstance.py:1037} INFO - Dependencies all met for <TaskInstance: s3_big5.s3filetransformoperator manual__2022-03-23T09:54:58.263272+00:00 [queued]>
[2022-03-23 09:54:59,458] {taskinstance.py:1243} INFO - 
--------------------------------------------------------------------------------
[2022-03-23 09:54:59,459] {taskinstance.py:1244} INFO - Starting attempt 1 of 1
[2022-03-23 09:54:59,459] {taskinstance.py:1245} INFO - 
--------------------------------------------------------------------------------
[2022-03-23 09:54:59,479] {taskinstance.py:1264} INFO - Executing <Task(S3FileTransformOperator): s3filetransformoperator> on 2022-03-23 09:54:58.263272+00:00
[2022-03-23 09:54:59,485] {standard_task_runner.py:52} INFO - Started process 3193 to run task
[2022-03-23 09:54:59,491] {standard_task_runner.py:76} INFO - Running: ['***', 'tasks', 'run', 's3_big5', 's3filetransformoperator', 'manual__2022-03-23T09:54:58.263272+00:00', '--job-id', '41', '--raw', '--subdir', 'DAGS_FOLDER/s3_big5.py', '--cfg-path', '/tmp/tmpsech8jep', '--error-file', '/tmp/tmp98ys4_sf']
[2022-03-23 09:54:59,492] {standard_task_runner.py:77} INFO - Job 41: Subtask s3filetransformoperator
[2022-03-23 09:54:59,573] {logging_mixin.py:109} INFO - Running <TaskInstance: s3_big5.s3filetransformoperator manual__2022-03-23T09:54:58.263272+00:00 [running]> on host c15ce74e6b9e
[2022-03-23 09:54:59,647] {taskinstance.py:1431} INFO - Exporting the following env vars:
AIRFLOW_CTX_DAG_OWNER=***
AIRFLOW_CTX_DAG_ID=s3_big5
AIRFLOW_CTX_TASK_ID=s3filetransformoperator
AIRFLOW_CTX_EXECUTION_DATE=2022-03-23T09:54:58.263272+00:00
AIRFLOW_CTX_DAG_RUN_ID=manual__2022-03-23T09:54:58.263272+00:00
[2022-03-23 09:54:59,648] {s3.py:466} INFO - Downloading source S3 file s3://testbig5src/big5_file.txt
[2022-03-23 09:54:59,674] {base_aws.py:190} INFO - Credentials retrieved from login
[2022-03-23 09:55:00,945] {base_aws.py:190} INFO - Credentials retrieved from login
[2022-03-23 09:55:02,187] {s3.py:472} INFO - Dumping S3 file s3://testbig5src/big5_file.txt contents to local file /tmp/tmps71suhbe
[2022-03-23 09:55:02,761] {taskinstance.py:1718} ERROR - Task failed with exception
Traceback (most recent call last):
  File "/home/airflow/.local/lib/python3.7/site-packages/airflow/models/taskinstance.py", line 1334, in _run_raw_task
    self._execute_task_with_callbacks(context)
  File "/home/airflow/.local/lib/python3.7/site-packages/airflow/models/taskinstance.py", line 1460, in _execute_task_with_callbacks
    result = self._execute_task(context, self.task)
  File "/home/airflow/.local/lib/python3.7/site-packages/airflow/models/taskinstance.py", line 1516, in _execute_task
    result = execute_callable(context=context)
  File "/home/airflow/.local/lib/python3.7/site-packages/airflow/providers/amazon/aws/operators/s3.py", line 475, in execute
    content = source_s3.select_key(key=self.source_s3_key, expression=self.select_expression)
  File "/home/airflow/.local/lib/python3.7/site-packages/airflow/providers/amazon/aws/hooks/s3.py", line 62, in wrapper
    return func(*bound_args.args, **bound_args.kwargs)
  File "/home/airflow/.local/lib/python3.7/site-packages/airflow/providers/amazon/aws/hooks/s3.py", line 90, in wrapper
    return func(*bound_args.args, **bound_args.kwargs)
  File "/home/airflow/.local/lib/python3.7/site-packages/airflow/providers/amazon/aws/hooks/s3.py", line 398, in select_key
    OutputSerialization=output_serialization,
  File "/home/airflow/.local/lib/python3.7/site-packages/botocore/client.py", line 391, in _api_call
    return self._make_api_call(operation_name, kwargs)
  File "/home/airflow/.local/lib/python3.7/site-packages/botocore/client.py", line 719, in _make_api_call
    raise error_class(parsed_response, operation_name)
botocore.exceptions.ClientError: An error occurred (InvalidTextEncoding) when calling the SelectObjectContent operation: UTF-8 encoding is required. The text encoding error was found near byte 10.
[2022-03-23 09:55:02,778] {taskinstance.py:1282} INFO - Marking task as FAILED. dag_id=s3_big5, task_id=s3filetransformoperator, execution_date=20220323T095458, start_date=20220323T095459, end_date=20220323T095502
[2022-03-23 09:55:02,804] {standard_task_runner.py:92} ERROR - Failed to execute job 41 for task s3filetransformoperator
Traceback (most recent call last):
  File "/home/airflow/.local/lib/python3.7/site-packages/airflow/task/task_runner/standard_task_runner.py", line 85, in _start_by_fork
    args.func(args, dag=self.dag)
  File "/home/airflow/.local/lib/python3.7/site-packages/airflow/cli/cli_parser.py", line 48, in command
    return func(*args, **kwargs)
  File "/home/airflow/.local/lib/python3.7/site-packages/airflow/utils/cli.py", line 92, in wrapper
    return f(*args, **kwargs)
  File "/home/airflow/.local/lib/python3.7/site-packages/airflow/cli/commands/task_command.py", line 298, in task_run
    _run_task_by_selected_method(args, dag, ti)
  File "/home/airflow/.local/lib/python3.7/site-packages/airflow/cli/commands/task_command.py", line 107, in _run_task_by_selected_method
    _run_raw_task(args, ti)
  File "/home/airflow/.local/lib/python3.7/site-packages/airflow/cli/commands/task_command.py", line 184, in _run_raw_task
    error_file=args.error_file,
  File "/home/airflow/.local/lib/python3.7/site-packages/airflow/utils/session.py", line 70, in wrapper
    return func(*args, session=session, **kwargs)
  File "/home/airflow/.local/lib/python3.7/site-packages/airflow/models/taskinstance.py", line 1334, in _run_raw_task
    self._execute_task_with_callbacks(context)
  File "/home/airflow/.local/lib/python3.7/site-packages/airflow/models/taskinstance.py", line 1460, in _execute_task_with_callbacks
    result = self._execute_task(context, self.task)
  File "/home/airflow/.local/lib/python3.7/site-packages/airflow/models/taskinstance.py", line 1516, in _execute_task
    result = execute_callable(context=context)
  File "/home/airflow/.local/lib/python3.7/site-packages/airflow/providers/amazon/aws/operators/s3.py", line 475, in execute
    content = source_s3.select_key(key=self.source_s3_key, expression=self.select_expression)
  File "/home/airflow/.local/lib/python3.7/site-packages/airflow/providers/amazon/aws/hooks/s3.py", line 62, in wrapper
    return func(*bound_args.args, **bound_args.kwargs)
  File "/home/airflow/.local/lib/python3.7/site-packages/airflow/providers/amazon/aws/hooks/s3.py", line 90, in wrapper
    return func(*bound_args.args, **bound_args.kwargs)
  File "/home/airflow/.local/lib/python3.7/site-packages/airflow/providers/amazon/aws/hooks/s3.py", line 398, in select_key
    OutputSerialization=output_serialization,
  File "/home/airflow/.local/lib/python3.7/site-packages/botocore/client.py", line 391, in _api_call
    return self._make_api_call(operation_name, kwargs)
  File "/home/airflow/.local/lib/python3.7/site-packages/botocore/client.py", line 719, in _make_api_call
    raise error_class(parsed_response, operation_name)
botocore.exceptions.ClientError: An error occurred (InvalidTextEncoding) when calling the SelectObjectContent operation: UTF-8 encoding is required. The text encoding error was found near byte 10.
[2022-03-23 09:55:02,827] {local_task_job.py:154} INFO - Task exited with return code 1
[2022-03-23 09:55:02,894] {local_task_job.py:264} INFO - 0 downstream tasks scheduled from follow-on schedule check
