[2022-03-23 09:54:59,396] {taskinstance.py:1037} INFO - Dependencies all met for <TaskInstance: s3_big5.s3hook_selectkey manual__2022-03-23T09:54:58.263272+00:00 [queued]>
[2022-03-23 09:54:59,411] {taskinstance.py:1037} INFO - Dependencies all met for <TaskInstance: s3_big5.s3hook_selectkey manual__2022-03-23T09:54:58.263272+00:00 [queued]>
[2022-03-23 09:54:59,412] {taskinstance.py:1243} INFO - 
--------------------------------------------------------------------------------
[2022-03-23 09:54:59,412] {taskinstance.py:1244} INFO - Starting attempt 1 of 1
[2022-03-23 09:54:59,412] {taskinstance.py:1245} INFO - 
--------------------------------------------------------------------------------
[2022-03-23 09:54:59,430] {taskinstance.py:1264} INFO - Executing <Task(PythonOperator): s3hook_selectkey> on 2022-03-23 09:54:58.263272+00:00
[2022-03-23 09:54:59,435] {standard_task_runner.py:52} INFO - Started process 3192 to run task
[2022-03-23 09:54:59,439] {standard_task_runner.py:76} INFO - Running: ['***', 'tasks', 'run', 's3_big5', 's3hook_selectkey', 'manual__2022-03-23T09:54:58.263272+00:00', '--job-id', '42', '--raw', '--subdir', 'DAGS_FOLDER/s3_big5.py', '--cfg-path', '/tmp/tmptmagwrfs', '--error-file', '/tmp/tmpbhvumxxb']
[2022-03-23 09:54:59,440] {standard_task_runner.py:77} INFO - Job 42: Subtask s3hook_selectkey
[2022-03-23 09:54:59,525] {logging_mixin.py:109} INFO - Running <TaskInstance: s3_big5.s3hook_selectkey manual__2022-03-23T09:54:58.263272+00:00 [running]> on host c15ce74e6b9e
[2022-03-23 09:54:59,601] {taskinstance.py:1431} INFO - Exporting the following env vars:
AIRFLOW_CTX_DAG_OWNER=***
AIRFLOW_CTX_DAG_ID=s3_big5
AIRFLOW_CTX_TASK_ID=s3hook_selectkey
AIRFLOW_CTX_EXECUTION_DATE=2022-03-23T09:54:58.263272+00:00
AIRFLOW_CTX_DAG_RUN_ID=manual__2022-03-23T09:54:58.263272+00:00
[2022-03-23 09:54:59,614] {base_aws.py:190} INFO - Credentials retrieved from login
[2022-03-23 09:55:01,195] {taskinstance.py:1718} ERROR - Task failed with exception
Traceback (most recent call last):
  File "/home/airflow/.local/lib/python3.7/site-packages/airflow/models/taskinstance.py", line 1334, in _run_raw_task
    self._execute_task_with_callbacks(context)
  File "/home/airflow/.local/lib/python3.7/site-packages/airflow/models/taskinstance.py", line 1460, in _execute_task_with_callbacks
    result = self._execute_task(context, self.task)
  File "/home/airflow/.local/lib/python3.7/site-packages/airflow/models/taskinstance.py", line 1516, in _execute_task
    result = execute_callable(context=context)
  File "/home/airflow/.local/lib/python3.7/site-packages/airflow/operators/python.py", line 174, in execute
    return_value = self.execute_callable()
  File "/home/airflow/.local/lib/python3.7/site-packages/airflow/operators/python.py", line 188, in execute_callable
    return self.python_callable(*self.op_args, **self.op_kwargs)
  File "/opt/airflow/dags/s3_big5.py", line 28, in _s3hook_selectkey
    file_content = s3.select_key(key, bucket)
  File "/home/airflow/.local/lib/python3.7/site-packages/airflow/providers/amazon/aws/hooks/s3.py", line 62, in wrapper
    return func(*bound_args.args, **bound_args.kwargs)
  File "/home/airflow/.local/lib/python3.7/site-packages/airflow/providers/amazon/aws/hooks/s3.py", line 90, in wrapper
    return func(*bound_args.args, **bound_args.kwargs)
  File "/home/airflow/.local/lib/python3.7/site-packages/airflow/providers/amazon/aws/hooks/s3.py", line 398, in select_key
    OutputSerialization=output_serialization,
  File "/home/airflow/.local/lib/python3.7/site-packages/botocore/client.py", line 391, in _api_call
    return self._make_api_call(operation_name, kwargs)
  File "/home/airflow/.local/lib/python3.7/site-packages/botocore/client.py", line 719, in _make_api_call
    raise error_class(parsed_response, operation_name)
botocore.exceptions.ClientError: An error occurred (InvalidTextEncoding) when calling the SelectObjectContent operation: UTF-8 encoding is required. The text encoding error was found near byte 43.
[2022-03-23 09:55:01,251] {taskinstance.py:1282} INFO - Marking task as FAILED. dag_id=s3_big5, task_id=s3hook_selectkey, execution_date=20220323T095458, start_date=20220323T095459, end_date=20220323T095501
[2022-03-23 09:55:01,317] {standard_task_runner.py:92} ERROR - Failed to execute job 42 for task s3hook_selectkey
Traceback (most recent call last):
  File "/home/airflow/.local/lib/python3.7/site-packages/airflow/task/task_runner/standard_task_runner.py", line 85, in _start_by_fork
    args.func(args, dag=self.dag)
  File "/home/airflow/.local/lib/python3.7/site-packages/airflow/cli/cli_parser.py", line 48, in command
    return func(*args, **kwargs)
  File "/home/airflow/.local/lib/python3.7/site-packages/airflow/utils/cli.py", line 92, in wrapper
    return f(*args, **kwargs)
  File "/home/airflow/.local/lib/python3.7/site-packages/airflow/cli/commands/task_command.py", line 298, in task_run
    _run_task_by_selected_method(args, dag, ti)
  File "/home/airflow/.local/lib/python3.7/site-packages/airflow/cli/commands/task_command.py", line 107, in _run_task_by_selected_method
    _run_raw_task(args, ti)
  File "/home/airflow/.local/lib/python3.7/site-packages/airflow/cli/commands/task_command.py", line 184, in _run_raw_task
    error_file=args.error_file,
  File "/home/airflow/.local/lib/python3.7/site-packages/airflow/utils/session.py", line 70, in wrapper
    return func(*args, session=session, **kwargs)
  File "/home/airflow/.local/lib/python3.7/site-packages/airflow/models/taskinstance.py", line 1334, in _run_raw_task
    self._execute_task_with_callbacks(context)
  File "/home/airflow/.local/lib/python3.7/site-packages/airflow/models/taskinstance.py", line 1460, in _execute_task_with_callbacks
    result = self._execute_task(context, self.task)
  File "/home/airflow/.local/lib/python3.7/site-packages/airflow/models/taskinstance.py", line 1516, in _execute_task
    result = execute_callable(context=context)
  File "/home/airflow/.local/lib/python3.7/site-packages/airflow/operators/python.py", line 174, in execute
    return_value = self.execute_callable()
  File "/home/airflow/.local/lib/python3.7/site-packages/airflow/operators/python.py", line 188, in execute_callable
    return self.python_callable(*self.op_args, **self.op_kwargs)
  File "/opt/airflow/dags/s3_big5.py", line 28, in _s3hook_selectkey
    file_content = s3.select_key(key, bucket)
  File "/home/airflow/.local/lib/python3.7/site-packages/airflow/providers/amazon/aws/hooks/s3.py", line 62, in wrapper
    return func(*bound_args.args, **bound_args.kwargs)
  File "/home/airflow/.local/lib/python3.7/site-packages/airflow/providers/amazon/aws/hooks/s3.py", line 90, in wrapper
    return func(*bound_args.args, **bound_args.kwargs)
  File "/home/airflow/.local/lib/python3.7/site-packages/airflow/providers/amazon/aws/hooks/s3.py", line 398, in select_key
    OutputSerialization=output_serialization,
  File "/home/airflow/.local/lib/python3.7/site-packages/botocore/client.py", line 391, in _api_call
    return self._make_api_call(operation_name, kwargs)
  File "/home/airflow/.local/lib/python3.7/site-packages/botocore/client.py", line 719, in _make_api_call
    raise error_class(parsed_response, operation_name)
botocore.exceptions.ClientError: An error occurred (InvalidTextEncoding) when calling the SelectObjectContent operation: UTF-8 encoding is required. The text encoding error was found near byte 43.
[2022-03-23 09:55:01,380] {local_task_job.py:154} INFO - Task exited with return code 1
[2022-03-23 09:55:01,523] {local_task_job.py:264} INFO - 0 downstream tasks scheduled from follow-on schedule check
